Workbook
Name \_JUNK: #N/A
Name \0: #N/A
Name \a: '[1]FF-21(a)'!#REF!
Name \c: '[1]FF-21(a)'!#REF!
Name \d: #N/A
Name \h: #N/A
Name \l: #N/A
Name \p: #N/A
Name _: "$#REF!.$A$6:$D$13"
Name _____a21420: #REF!
Name _____a21430: #REF!
Name _____a22220: #REF!
Name _____a22241: #REF!
Name _____a22242: #REF!
Name _____a22260: #REF!
Name _____a22270: #REF!
Name _____a24385: #REF!
Name _____a24391: #REF!
Name _____a24392: #REF!
Name _____a24393: #REF!
Name _____a24394: #REF!
Name _____a27120: #REF!
Name _____a27150: #REF!
Name _____a32320: #REF!
Name _____a32730: #REF!
Name _____a33130: #REF!
Name _____a33140: #REF!
Name _____a33160: #REF!
Name _____a33170: #REF!
Name _____a33190: #REF!
Name _____a33210: #REF!
Name _____a33230: #REF!
Name _____a33240: #REF!
Name _____a34010: #REF!
Name _____a41230: #REF!
Name _____a41240: #REF!
Name _____a42781: #REF!
Name _____a42782: #REF!
Name _____a42783: #REF!
Name _____A43220: #REF!
Name _____a43230: #REF!
Name _____a43260: #REF!
Name _____a43270: #REF!
Name _____a43320: #REF!
Name _____a43330: #REF!
Name _____a43360: #REF!
Name _____a43370: #REF!
Name _____a43530: #REF!
Name _____a43540: #REF!
Name _____a43560: #REF!
Name _____a43570: #REF!
Name _____a43630: #REF!
Name _____a43640: #REF!
Name _____a43660: #REF!
Name _____a43670: #REF!
Name _____a43730: #REF!
Name _____a43750: #REF!
Name _____a43760: #REF!
Name _____a43770: #REF!
Name _____a43780: #REF!

Sheet TB
A1: YWX HOLDING PTE LTD
A2: YEAR ENDED 31.5.2024
A4: TRIAL BALANCE WORKSHEET
A6: Description | C6: Trial balance | F6: Adjustment | I6: Adjustment | L6: Adjusted trial balances
C7: DR | D7: CR | F7: DR | G7: DR | I7: CR | J7: CR | L7: DR | M7: CR
C8: S$ | D8: S$ | F8: S$ | G8: S$ | I8: S$ | J8: S$ | L8: S$ | M8: S$
A10: OCBC - SGD | C10: =总帐!D38 -> 9568.82 | L10: =IF(SUM($C10:$J10)>0,SUM($C10:$J10),0) -> 9568.82 | M10: =IF(SUM($C10:$J10)<0,SUM($C10:$J10),0) -> 0
A11: OCBC - USD | C11: =总帐!F38 -> 5.976976 | L11: =IF(SUM($C11:$J11)>0,SUM($C11:$J11),0) -> 5.976976 | M11: =IF(SUM($C11:$J11)<0,SUM($C11:$J11),0) -> 0 | N11: =SUM(L10:M11) -> 9574.797
A13: Investment in MDK (Zhejiang) | C13: =总帐!I38 -> 2312380 | L13: =IF(SUM($C13:$J13)>0,SUM($C13:$J13),0) -> 2312380 | M13: =IF(SUM($C13:$J13)<0,SUM($C13:$J13),0) -> 0
A14: Deposit paid | C14: =总帐!J38 -> 0 | L14: =IF(SUM($C14:$J14)>0,SUM($C14:$J14),0) -> 0 | M14: =IF(SUM($C14:$J14)<0,SUM($C14:$J14),0) -> 0
A16: Deposit received | D16: =总帐!K38 -> -1650 | L16: =IF(SUM($C16:$J16)>0,SUM($C16:$J16),0) -> 0 | M16: =IF(SUM($C16:$J16)<0,SUM($C16:$J16),0) -> -1650
A17: Loan from shareholders | D17: =总帐!M38 -> -2312380 | L17: =IF(SUM($C17:$J17)>0,SUM($C17:$J17),0) -> 0 | M17: =IF(SUM($C17:$J17)<0,SUM($C17:$J17),0) -> -2312380
A18: Accruals | D18: =总帐!L38 -> 0 | L18: =IF(SUM($C18:$J18)>0,SUM($C18:$J18),0) -> 0 | M18: =IF(SUM($C18:$J18)<0,SUM($C18:$J18),0) -> 0 | N18: =SUM(L16:M18) -> -2314030
A20: Share capital | D20: =总帐!G38 -> -10000 | L20: =IF(SUM($C20:$J20)>0,SUM($C20:$J20),0) -> 0 | M20: =IF(SUM($C20:$J20)<0,SUM($C20:$J20),0) -> -10000
A21: Retained earnings | C21: =总帐!H9 -> 275.38 | L21: =IF(SUM($C21:$J21)>0,SUM($C21:$J21),0) -> 275.38 | M21: =IF(SUM($C21:$J21)<0,SUM($C21:$J21),0) -> 0
C23: =SUM(C10:C22) -> 2322230.2 | D23: =SUM(D10:D22) -> -2324030 | L23: =SUM(L10:L22) -> 2322230.2 | M23: =SUM(M10:M22) -> -2324030
A24: Net loss for the year | C24: =IF($C$23+$D$23<0,-($C$23+$D$23),0) -> 1799.823 | D24: =IF($C$23+$D$23>0,-($C$23+$D$23),0) -> 0 | L24: =IF($L$23+$M$23<0,-($L$23+$M$23),0) -> 1799.823 | M24: =IF($L$23+$M$23>0,-($L$23+$M$23),0) -> 0 | N24: =M20+M21+M24 -> -10000 | O24: =L21+L24 -> 2075.203
C25: =SUM(C23:C24) -> 2324030 | D25: =SUM(D23:D24) -> -2324030 | L25: =SUM(L23:L24) -> 2324030 | M25: =SUM(M23:M24) -> -2324030 | O25: =M20+O24 -> -7924.797
A28: Management fees received | D28: =总帐!Q38 -> -2700 | L28: =IF(SUM($C28:$J28)>0,SUM($C28:$J28),0) -> 0 | M28: =IF(SUM($C28:$J28)<0,SUM($C28:$J28),0) -> -2700
A29: Other Icome | D29: =总帐!R38 -> -16.8 | L29: =IF(SUM($C29:$J29)>0,SUM($C29:$J29),0) -> 0 | M29: =IF(SUM($C29:$J29)<0,SUM($C29:$J29),0) -> -16.8
A30: Bank charges | C30: =总帐!S38 -> 455.82 | L30: =IF(SUM($C30:$J30)>0,SUM($C30:$J30),0) -> 455.82 | M30: =IF(SUM($C30:$J30)<0,SUM($C30:$J30),0) -> 0
A31: Accountancy & secretarial fees | C31: =总帐!T38 -> 792 | L31: =IF(SUM($C31:$J31)>0,SUM($C31:$J31),0) -> 792 | M31: =IF(SUM($C31:$J31)<0,SUM($C31:$J31),0) -> 0
A32: Genearl expenses | C32: =总帐!U38 -> 497.44 | L32: =IF(SUM($C32:$J32)>0,SUM($C32:$J32),0) -> 497.44 | M32: =IF(SUM($C32:$J32)<0,SUM($C32:$J32),0) -> 0
A33: Rent paid | C33: =总帐!V38 -> 2376 | L33: =IF(SUM($C33:$J33)>0,SUM($C33:$J33),0) -> 2376 | M33: =IF(SUM($C33:$J33)<0,SUM($C33:$J33),0) -> 0
A34: Telephone & internet | C34: =总帐!W38 -> 186.36 | L34: =IF(SUM($C34:$J34)>0,SUM($C34:$J34),0) -> 186.36 | M34: =IF(SUM($C34:$J34)<0,SUM($C34:$J34),0) -> 0
A35: Transport expenses | C35: =总帐!X38 -> 0 | L35: =IF(SUM($C35:$J35)>0,SUM($C35:$J35),0) -> 0 | M35: =IF(SUM($C35:$J35)<0,SUM($C35:$J35),0) -> 0
A36: Water & electricity | C36: =总帐!Y38 -> 209 | L36: =IF(SUM($C36:$J36)>0,SUM($C36:$J36),0) -> 209 | M36: =IF(SUM($C36:$J36)<0,SUM($C36:$J36),0) -> 0
A37: Gain in exchange | D37: =总帐!Z38 -> 0 | L37: =IF(SUM($C37:$J37)>0,SUM($C37:$J37),0) -> 0 | M37: =IF(SUM($C37:$J37)<0,SUM($C37:$J37),0) -> 0
C39: =SUM(C29:C37) -> 4516.62 | D39: =SUM(D28:D37) -> -2716.8 | L39: =SUM(L29:L37) -> 4516.62 | M39: =SUM(M28:M37) -> -2716.8
A40: =A24 -> Net loss for the year | C40: =IF($C$39+$D$39<0,-($C$39+$D$39),0) -> 0 | D40: =IF($C$39+$D$39>0,-($C$39+$D$39),0) -> -1799.82 | L40: =IF($L$39+$M$39<0,-($L$39+$M$39),0) -> 0 | M40: =IF($L$39+$M$39>0,-($L$39+$M$39),0) -> -1799.82
C41: =SUM(C39:C40) -> 4516.62 | D41: =SUM(D39:D40) -> -4516.62 | L41: =SUM(L39:L40) -> 4516.62 | M41: =SUM(M39:M40) -> -4516.62
A43: Net profit before tax | M43: =-L40 -> 0
A44: Income tax expense | F44: =[43]JE!F26 -> 9483.96 | L44: =IF(SUM($C44:$J44)>0,SUM($C44:$J44),0) -> 9483.96 | M44: =IF(SUM($C44:$J44)<0,SUM($C44:$J44),0) -> 0
A45: Net profit after tax | L45: =SUM(L43:M44)*-1 -> -9483.96 | M45: 0
L46: =SUM(L44:L45) -> 0 | M46: =SUM(M43:M45) -> 0

Sheet 总帐
A1: YWX HOLDING PTE LTD
A3: BANK TRANSACTION DETAILS FOR YEAR ENDED 31.5.2024
A6: Date | B6: Ref. | C6: Descriptions | D6: OCBC SGD | E6: OCBC - USD | G6: Share capital | H6: Retained earnings | I6: Investment in MDK (Zhejiang) | J6: Deposit paid | K6: Deposit received | L6: Accruals | M6: Loan from shareholders | Q6: Management fees rec'd | R6: Misc income | S6: Bank charges | T6: Acc. & Sec. fees | U6: General expenses | V6: Rent paid | W6: Telephone & internet | X6: Transport | Y6: Utilities | Z6: Gain in exchange | AB6: Total
D7: S$ | E7: US$ | F7: S$ | G7: S$ | H7: S$ | J7: S$ | K7: S$ | L7: S$ | M7: S$ | N7: S$ | O7: S$ | Q7: S$ | R7: S$ | S7: S$ | T7: S$ | U7: S$ | V7: S$ | W7: S$ | X7: S$ | Y7: S$ | Z7: S$ | AA7: S$ | AB7: S$
A9: 45078 | C9: Balance b/d | D9: 10862.82 | E9: 248.50066 | F9: 341.79698 | G9: -10000 | H9: 275.38 | I9: 2312380 | J9: 4570 | K9: -6050 | L9: 0 | M9: -2312380 | AB9: =SUM(D9:AA9) -> 248.49764
A10: 45082 | C10: Bank charges | D10: -10 | S10: =-D10 -> 10 | AB10: =SUM(D10:AA10) -> 0
A11: 45092 | C11: MMT SG Pte Ltd - office rent Jun 23 | D11: -2376 | V11: =-D11 -> 2376 | AB11: =SUM(D11:AA11) -> 0
A12: 45092 | C12: MDK (S) - Office rent Jun 23 | D12: 2700 | Q12: =-D12 -> -2700 | AB12: =SUM(D12:AA12) -> 0
A13: 45104 | C13: M1 bills for Jun 2023 | D13: -109 | W13: =-D13 -> 109 | AB13: =SUM(D13:AA13) -> 0
A14: 45106 | C14: ACRA-Certificate confirming incorporationof company | D14: -50 | U14: 50 | AB14: =SUM(D14:AA14) -> 0
A15: 45110 | C15: Bank charges | D15: -10 | S15: =-D15 -> 10 | AB15: =SUM(D15:AA15) -> 0
A16: 45117 | C16: Utility fees paid | D16: -129.46 | Y16: =-D16 -> 129.46 | AB16: =SUM(D16:AA16) -> 0
A17: =A16 -> 45117 | C17: Utility fees rec'd - Ban Leong | D17: 16.8 | R17: =-D17 -> -16.8 | AB17: =SUM(D17:AA17) -> 0
A18: 45124 | C18: Double Axis PL - refund of rental deposits | D18: 4400 | J18: =-D18 -> -4400 | AB18: =SUM(D18:AA18) -> 0
A19: =A18 -> 45124 | C19: Refund deposit to MDK | D19: -4400 | K19: =-D19 -> 4400 | AB19: =SUM(D19:AA19) -> 0
A20: 45134 | C20: SP Services refund | D20: 90.46 | J20: =-D20 -> -90.46 | AB20: =SUM(D20:AA20) -> 0
A21: 45141 | C21: Bank charges | D21: -10 | S21: =-D21 -> 10 | AB21: =SUM(D21:AA21) -> 0
A22: 45160 | B22: INV-6552 | C22: W.L.P Pte Ltd - secretarial fees | D22: -492 | T22: =-D22 -> 492 | AB22: =SUM(D22:AA22) -> 0
A23: 45160 | C23: Accountancy fees | D23: -300 | T23: =-D23 -> 300 | AB23: =SUM(D23:AA23) -> 0
A24: 45173 | C24: Bank charges | D24: -10 | S24: =-D24 -> 10 | AB24: =SUM(D24:AA24) -> 0
A25: 45194 | C25: M1 bills | D25: -77.36 | W25: =-D25 -> 77.36 | AB25: =SUM(D25:AA25) -> 0
A26: 45195 | B26: WR209760 | C26: Worsbug - translation fees | D26: -447.44 | U26: =-D26 -> 447.44 | AB26: =SUM(D26:AA26) -> 0
A27: 45202 | C27: Bank charges | D27: -10 | S27: =-D27 -> 10 | AB27: =SUM(D27:AA27) -> 0
A28: 45233 | C28: Bank charges | D28: -10 | S28: =-D28 -> 10 | AB28: =SUM(D28:AA28) -> 0
A29: 45263 | C29: Bank charges | D29: -10 | S29: =-D29 -> 10 | AB29: =SUM(D29:AA29) -> 0
A30: 45294 | C30: Bank charges | D30: -10 | S30: =-D30 -> 10 | AB30: =SUM(D30:AA30) -> 0
A31: 45325 | C31: Bank charges | D31: -10 | S31: =-D31 -> 10 | AB31: =SUM(D31:AA31) -> 0
A32: 45354 | C32: Bank charges | D32: -10 | S32: =-D32 -> 10 | AB32: =SUM(D32:AA32) -> 0
A33: 45385 | C33: Bank charges | D33: -10 | S33: =-D33 -> 10 | AB33: =SUM(D33:AA33) -> 0
A34: 45415 | C34: Bank charges | D34: -10 | S34: =-D34 -> 10 | AB34: =SUM(D34:AA34) -> 0
A35: 45443 | B35: JE(1) | C35: Utilities adjusted | J35: -79.54 | Y35: 79.54 | AB35: =SUM(D35:AA35) -> 0
A36: 45443 | B36: JE(2) | C36: Bank charges for USD a/c | E36: =4.43-248.5 -> -244.07 | F36: =5.98-341.8 -> -335.82 | S36: =-F36 -> 335.82 | AB36: =SUM(F36:AA36) -> 0
AB37: =SUM(D37:AA37) -> 0
D38: =SUM(D9:D37) -> 9568.82 | E38: =SUM(E9:E37) -> 4.4306606 | F38: =SUM(F9:F37) -> 5.976976 | G38: =SUM(G9:G37) -> -10000 | H38: =SUM(H9:H37) -> 275.38 | I38: =SUM(I9:I37) -> 2312380 | J38: =SUM(J9:J37) -> 0 | K38: =SUM(K9:K37) -> -1650 | ... O38: =SUM(O9:O37) -> 0 | Q38: =SUM(Q9:Q37) -> -2700 | R38: =SUM(R9:R37) -> -16.8 | S38: =SUM(S9:S37) -> 455.82 | T38: =SUM(T9:T37) -> 792 | U38: =SUM(U9:U37) -> 497.44 | V38: =SUM(V9:V37) -> 2376 | W38: =SUM(W9:W37) -> 186.36 | X38: =SUM(X9:X37) -> 0 | ... AA38: =SUM(AA9:AA37) -> 0 | AB38: =SUM(F38:AA38) -> -9568.823
AB40: =SUM(R38:Z38)+SUM(G38:K38) -> 2305505.2

Sheet Exchange.rate
A1: MAS: Financial Database - Exchange Rates
A3: Exchange Rates (Monthly)
A4: Jun 2021 to Jun 2024
A7: End of Period | C7: S$ Per Unit of US Dollar
A8: 2021 | B8: Jun | C8: 1.3444
B9: Jul | C9: 1.3534
B10: Aug | C10: 1.3445
B11: Sep | C11: 1.3611
B12: Oct | C12: 1.3444
B13: Nov | C13: 1.3686
B14: Dec | C14: 1.3517
A15: 2022 | B15: Jan | C15: 1.3557
B16: Feb | C16: 1.3597
B17: Mar | C17: 1.3534
B18: Apr | C18: 1.3848
B19: May | C19: 1.3697
B20: Jun | C20: 1.3918
B21: Jul | C21: 1.3785
B22: Aug | C22: 1.395
B23: Sep | C23: 1.434
B24: Oct | C24: 1.4112
B25: Nov | C25: 1.3722
B26: Dec | C26: 1.3446
A27: 2023 | B27: Jan | C27: 1.3142
B28: Feb | C28: 1.348
B29: Mar | C29: 1.327
B30: Apr | C30: 1.334
B31: May | C31: 1.3539
B32: Jun | C32: 1.3557
B33: Jul | C33: 1.3318
B34: Aug | C34: 1.3503
B35: Sep | C35: 1.3648
B36: Oct | C36: 1.3669
B37: Nov | C37: 1.3316
B38: Dec | C38: 1.3186
A39: 2024 | B39: Jan | C39: 1.3409
B40: Feb | C40: 1.3446
B41: Mar | C41: 1.3476
B42: Apr | C42: 1.3612
B43: May | C43: 1.3507
...

Sheet Journal
A1: YWX HOLDING PTE LTD
A2: YEAR ENDED 31.5.2023
A5: JOURNAL ENTRIES
F8: DR | H8: CR
F9: S$ | H9: S$
A11: 1 | B11: Utilities | F11: 79.54
C12: Utility deposit | H12: =F11 -> 79.54
B14: Being utility charges adjusted
A16: =A11+1 -> 2 | B16: Bank charges | F16: 335.82
C17: OCBC USD a/c | H17: =F16 -> 335.82
B19: Being bank charges taken up

Sheet Utilities
E1: Bank | G1: Offset deposit | I1: Refund deposit
A3: Deposit | K3: 1650
A4: 44378 | C4: 31.77 | E4: =C4 -> 31.77
A5: 44409 | C5: 183.96 | E5: =C5 -> 183.96
A6: 44440 | C6: 256.96 | E6: =C6 -> 256.96
A7: 44470 | C7: 273.29 | E7: =C7 -> 273.29
A8: 44501 | C8: 224.41 | E8: =C8 -> 224.41
A9: 44531 | C9: 215.16 | E9: =C9 -> 215.16
A10: 44562 | C10: 187.74 | E10: =C10 -> 187.74
I11: -1310 | K11: =K3+I11 -> 340
A12: 44593 | C12: =169.94+0.27+11.96+0.5 -> 182.67 | G12: =C12 -> 182.67 | I12: =I11+C12 -> -1127.33
A13: 44621 | C13: 90.37 | G13: =C13 -> 90.37 | I13: =I12+C13 -> -1036.96
A14: 44652 | C14: 112.92 | G14: =C14 -> 112.92 | I14: =I13+C14 -> -924.04
A15: 44682 | C15: 180.57 | G15: =C15 -> 180.57 | I15: =I14+C15 -> -743.47
C16: =SUM(C12:C15) -> 566.53
A18: 44713 | C18: 166.22 | G18: =C18 -> 166.22 | I18: =I15+C18 -> -577.25
A19: 44743 | C19: 213.73 | G19: =C19 -> 213.73 | I19: =I18+C19 -> -363.52
A20: 44774 | C20: 105.2 | G20: =C20 -> 105.2 | I20: =I19+C20 -> -258.32
A21: 44805 | C21: 94.88 | G21: =C21 -> 94.88 | I21: =I20+C21 -> -163.44
A22: 44835 | C22: 113.72 | G22: =C22 -> 113.72 | I22: =I21+C22 -> -49.72
A23: 44866 | C23: 138.46 | G23: =C23 -> 138.46 | I23: =I22+C23 -> 88.74
I24: -170 | K24: =K11+I24 -> 170
A25: 44896 | C25: =135.61+9.49 -> 145.1 | E25: 63.84 | G25: =C25-E25 -> 81.26 | I25: =I23+I24+C25-E25 -> 0
A26: 44927 | C26: 134.69 | E26: =C26 -> 134.69
A27: 44958 | C27: 112.56 | E27: =C27 -> 112.56
A28: 44986 | C28: =202.09-Utilities!C27 -> 89.53 | E28: =C28 -> 89.53
A29: 45017 | C29: 82.36 | E29: =C29 -> 82.36
A30: 45047 | C30: 123.12 | E30: =C30 -> 123.12
C31: =SUM(C18:C30) -> 1519.57
A33: 45078 | C33: 129.46 | E33: =C33 -> 129.46
A34: 45108

Sheet Company profile
A1: YWX HOLDING PTE LTD
A4: UEN No | B4: : | C4: 202119939E
A6: Incorporation date | B6: : | C6: 7/6/2021
A8: Registered office | B8: : | C8: 66 Elias Road #07-11 Oasis @ Elias, Singapore 519941
A10: Financial year end | B10: : | C10: May
A12: Director | B12: : | C12: Yu Qichuan
A14: Secretary | B14: : | C14: Tricia Wanxuan
C15: 100 Jalan Sultan #02-44, Sultan Plaza, Singapore 199001
A17: Shareholders and their shareholdings
D19: No of shares | F19: % held
C20: Yu Qichuan | D20: 4211 | F20: =D20/10000 -> 0.4211
C21: Xia Limin | D21: 1228 | F21: =D21/10000 -> 0.1228
C22: Wang Wei | D22: 2807 | F22: =D22/10000 -> 0.2807
C23: Wang Ji | D23: 1754 | F23: =D23/10000 -> 0.1754
D24: =SUM(D20:D23) -> 10000 | F24: =SUM(F20:F23) -> 1
