Workbook
Name \_JUNK: #N/A
Name \0: #N/A
Name \a: '[1]FF-21(a)'!#REF!
Name \c: '[1]FF-21(a)'!#REF!
Name \d: #N/A
Name \h: #N/A
Name \l: #N/A
Name \p: #N/A
Name _: "$#REF!.$A$6:$D$13"
Name _____a21420: #REF!
Name _____a21430: #REF!
Name _____a22220: #REF!
Name _____a22241: #REF!
Name _____a22242: #REF!
Name _____a22260: #REF!
Name _____a22270: #REF!
Name _____a24385: #REF!
Name _____a24391: #REF!
Name _____a24392: #REF!
Name _____a24393: #REF!
Name _____a24394: #REF!
Name _____a27120: #REF!
Name _____a27150: #REF!
Name _____a32320: #REF!
Name _____a32730: #REF!
Name _____a33130: #REF!
Name _____a33140: #REF!
Name _____a33160: #REF!
Name _____a33170: #REF!
Name _____a33190: #REF!
Name _____a33210: #REF!
Name _____a33230: #REF!
Name _____a33240: #REF!
Name _____a34010: #REF!
Name _____a41230: #REF!
Name _____a41240: #REF!
Name _____a42781: #REF!
Name _____a42782: #REF!
Name _____a42783: #REF!
Name _____A43220: #REF!
Name _____a43230: #REF!
Name _____a43260: #REF!
Name _____a43270: #REF!
Name _____a43320: #REF!
Name _____a43330: #REF!
Name _____a43360: #REF!
Name _____a43370: #REF!
Name _____a43530: #REF!
Name _____a43540: #REF!
Name _____a43560: #REF!
Name _____a43570: #REF!
Name _____a43630: #REF!
Name _____a43640: #REF!
Name _____a43660: #REF!
Name _____a43670: #REF!
Name _____a43730: #REF!
Name _____a43750: #REF!
Name _____a43760: #REF!
Name _____a43770: #REF!
Name _____a43780: #REF!

Sheet TB
A1: YWX HOLDING PTE LTD
A2: PERIOD ENDED 31.5.2022
A4: TRIAL BALANCE WORKSHEET
A6: Description | C6: Trial balance | F6: Adjustment | I6: Adjustment | L6: Adjusted trial balances
C7: DR | D7: CR | F7: DR | G7: DR | I7: CR | J7: CR | L7: DR | M7: CR
C8: S$ | D8: S$ | F8: S$ | G8: S$ | I8: S$ | J8: S$ | L8: S$ | M8: S$
A10: OCBC - SGD | C10: =总帐!D60 -> 9559.6 | L10: =IF(SUM($C10:$J10)>0,SUM($C10:$J10),0) -> 9559.6 | M10: =IF(SUM($C10:$J10)<0,SUM($C10:$J10),0) -> 0
A11: OCBC - USD | C11: =总帐!F60 -> 408.52698 | L11: =IF(SUM($C11:$J11)>0,SUM($C11:$J11),0) -> 408.52698 | M11: =IF(SUM($C11:$J11)<0,SUM($C11:$J11),0) -> 0 | N11: =SUM(L10:M11) -> 9968.127
A13: Investment in MDK (Zhejiang) | C13: =总帐!H60 -> 2312380 | L13: =IF(SUM($C13:$J13)>0,SUM($C13:$J13),0) -> 2312380 | M13: =IF(SUM($C13:$J13)<0,SUM($C13:$J13),0) -> 0
A14: Deposit paid | C14: =总帐!I60 -> 5483.47 | L14: =IF(SUM($C14:$J14)>0,SUM($C14:$J14),0) -> 5483.47 | M14: =IF(SUM($C14:$J14)<0,SUM($C14:$J14),0) -> 0
A16: Deposit received | D16: =总帐!J60 -> -6050 | L16: =IF(SUM($C16:$J16)>0,SUM($C16:$J16),0) -> 0 | M16: =IF(SUM($C16:$J16)<0,SUM($C16:$J16),0) -> -6050
A17: Loan from shareholders | D17: =总帐!M60 -> -2312380 | L17: =IF(SUM($C17:$J17)>0,SUM($C17:$J17),0) -> 0 | M17: =IF(SUM($C17:$J17)<0,SUM($C17:$J17),0) -> -2312380
A18: Accruals | D18: =总帐!K60 -> -216 | L18: =IF(SUM($C18:$J18)>0,SUM($C18:$J18),0) -> 0 | M18: =IF(SUM($C18:$J18)<0,SUM($C18:$J18),0) -> -216 | N18: =SUM(L16:M18) -> -2318646
A20: Share capital | D20: =总帐!G60 -> -10000 | L20: =IF(SUM($C20:$J20)>0,SUM($C20:$J20),0) -> 0 | M20: =IF(SUM($C20:$J20)<0,SUM($C20:$J20),0) -> -10000
A21: Retained earnings | L21: =IF(SUM($C21:$J21)>0,SUM($C21:$J21),0) -> 0 | M21: =IF(SUM($C21:$J21)<0,SUM($C21:$J21),0) -> 0
C23: =SUM(C10:C22) -> 2327831.6 | D23: =SUM(D10:D22) -> -2328646 | L23: =SUM(L10:L22) -> 2327831.6 | M23: =SUM(M10:M22) -> -2328646
A24: Net profit for the year | C24: =IF($C$23+$D$23<0,-($C$23+$D$23),0) -> 814.40302 | D24: =IF($C$23+$D$23>0,-($C$23+$D$23),0) -> 0 | L24: =IF($L$23+$M$23<0,-($L$23+$M$23),0) -> 814.40302 | M24: =IF($L$23+$M$23>0,-($L$23+$M$23),0) -> 0 | N24: =M20+M21+M24 -> -10000
C25: =SUM(C23:C24) -> 2328646 | D25: =SUM(D23:D24) -> -2328646 | L25: =SUM(L23:L24) -> 2328646 | M25: =SUM(M23:M24) -> -2328646
A28: Management fees received | D28: =总帐!Q60 -> -30420.29 | L28: =IF(SUM($C28:$J28)>0,SUM($C28:$J28),0) -> 0 | M28: =IF(SUM($C28:$J28)<0,SUM($C28:$J28),0) -> -30420.29
A29: Other Icome | D29: =总帐!R60 -> -564.8 | L29: =IF(SUM($C29:$J29)>0,SUM($C29:$J29),0) -> 0 | M29: =IF(SUM($C29:$J29)<0,SUM($C29:$J29),0) -> -564.8
A30: Bank charges | C30: =总帐!S60 -> 343.18012 | L30: =IF(SUM($C30:$J30)>0,SUM($C30:$J30),0) -> 343.18012 | M30: =IF(SUM($C30:$J30)<0,SUM($C30:$J30),0) -> 0
A31: Accountancy & secretarial fees | C31: =总帐!T60 -> 915 | L31: =IF(SUM($C31:$J31)>0,SUM($C31:$J31),0) -> 915 | M31: =IF(SUM($C31:$J31)<0,SUM($C31:$J31),0) -> 0
A32: Genearl expenses | C32: =总帐!U60 -> 19 | L32: =IF(SUM($C32:$J32)>0,SUM($C32:$J32),0) -> 19 | M32: =IF(SUM($C32:$J32)<0,SUM($C32:$J32),0) -> 0
A33: Rent paid | C33: =总帐!V60 -> 25894 | L33: =IF(SUM($C33:$J33)>0,SUM($C33:$J33),0) -> 25894 | M33: =IF(SUM($C33:$J33)<0,SUM($C33:$J33),0) -> 0
A34: Telephone & internet | C34: =总帐!W60 -> 1523 | L34: =IF(SUM($C34:$J34)>0,SUM($C34:$J34),0) -> 1523 | M34: =IF(SUM($C34:$J34)<0,SUM($C34:$J34),0) -> 0
A35: Transport expenses | C35: =总帐!X60 -> 1400 | L35: =IF(SUM($C35:$J35)>0,SUM($C35:$J35),0) -> 1400 | M35: =IF(SUM($C35:$J35)<0,SUM($C35:$J35),0) -> 0
A36: Water & electricity | C36: =总帐!Y60 -> 1939.82 | L36: =IF(SUM($C36:$J36)>0,SUM($C36:$J36),0) -> 1939.82 | M36: =IF(SUM($C36:$J36)<0,SUM($C36:$J36),0) -> 0
A37: Gain in exchange | D37: =总帐!Z60 -> -234.5071 | L37: =IF(SUM($C37:$J37)>0,SUM($C37:$J37),0) -> 0 | M37: =IF(SUM($C37:$J37)<0,SUM($C37:$J37),0) -> -234.5071
C39: =SUM(C29:C37) -> 32034 | D39: =SUM(D28:D37) -> -31219.597 | L39: =SUM(L29:L37) -> 32034 | M39: =SUM(M28:M37) -> -31219.597
A40: Net profit for the year | C40: =IF($C$39+$D$39<0,-($C$39+$D$39),0) -> 0 | D40: =IF($C$39+$D$39>0,-($C$39+$D$39),0) -> -814.40302 | L40: =IF($L$39+$M$39<0,-($L$39+$M$39),0) -> 0 | M40: =IF($L$39+$M$39>0,-($L$39+$M$39),0) -> -814.40302
C41: =SUM(C39:C40) -> 32034 | D41: =SUM(D39:D40) -> -32034 | L41: =SUM(L39:L40) -> 32034 | M41: =SUM(M39:M40) -> -32034
A43: Net profit before tax | M43: =-L40 -> 0
A44: Income tax expense | F44: =[43]JE!F26 -> 9483.96 | L44: =IF(SUM($C44:$J44)>0,SUM($C44:$J44),0) -> 9483.96 | M44: =IF(SUM($C44:$J44)<0,SUM($C44:$J44),0) -> 0
A45: Net profit after tax | L45: =SUM(L43:M44)*-1 -> -9483.96 | M45: 0
L46: =SUM(L44:L45) -> 0 | M46: =SUM(M43:M45) -> 0
F51: `

Sheet 总帐
A1: YWX HOLDING PTE LTD
A3: BANK TRANSACTION DETAILS
A6: Date | B6: Ref. | C6: Descriptions | D6: OCBC SGD | E6: OCBC - USD | G6: Share capital | H6: Investment in MDK (Zhejiang) | I6: Deposit paid | J6: Deposit received | K6: Accruals | M6: Loan from shareholders | Q6: Management fees rec'd | R6: Misc income | S6: Bank charges | T6: Incorproation & Sec.fees | U6: General expenses | V6: Rent paid | W6: Telephone & internet | X6: Transport | Y6: Utilities | Z6: Gain in exchange | AB6: Total
D7: S$ | E7: US$ | F7: S$ | G7: S$ | H7: S$ | I7: S$ | J7: S$ | K7: S$ | L7: S$ | M7: S$ | N7: S$ | O7: S$ | Q7: S$ | R7: S$ | S7: S$ | T7: S$ | U7: S$ | V7: S$ | W7: S$ | X7: S$ | Y7: S$ | Z7: S$ | AA7: S$ | AB7: S$
C9: Share capital | D9: 10000 | G9: =-D9 -> -10000 | AB9: =SUM(D9:AA9) -> 0
A10: 44452 | C10: Utility fees rec'd - Ban Leong | D10: 61.79 | R10: =-D10 -> -61.79 | AB10: =SUM(D10:AA10) -> 0
A11: 44468 | C11: Xia Limin - fund transfer | E11: 105000 | F11: =E11*1.3611 -> 142915.5 | M11: =-F11 -> -142915.5 | AB11: =SUM(F11:AA11) -> 0
A12: 44468 | C12: Bank charges | E12: -7.32 | F12: =E12*1.3611 -> -9.963252 | S12: =-F12 -> 9.963252 | AB12: =SUM(F12:AA12) -> 0
A13: 44473 | C13: Bank charges | D13: -10 | S13: =-D13 -> 10 | AB13: =SUM(D13:AA13) -> 0
A14: 44470 | C14: Yu Qichuan - fund transfer | E14: 130000 | F14: =E14*1.3646 -> 177398 | M14: =-F14 -> -177398 | AB14: =SUM(F14:AA14) -> 0
A15: 44470 | C15: Wang Wei - fund transfer | E15: 120000 | F15: =E15*1.3646 -> 163752 | M15: =-F15 -> -163752 | AB15: =SUM(F15:AA15) -> 0
A16: 44473 | C16: Wang Ji - fund transfer | E16: 105000 | F16: =E16*1.3646 -> 143283 | M16: =-F16 -> -143283 | AB16: =SUM(F16:AA16) -> 0
A17: 44473 | C17: Bank charges | E17: -7.32 | F17: =E17*1.3646 -> -9.988872 | S17: =-F17 -> 9.988872 | AB17: =SUM(F17:AA17) -> 0
A18: 44473 | C18: Yu Qichuan - fund transfer | E18: 125000 | F18: =E18*1.3646 -> 170575 | M18: =-F18 -> -170575 | AB18: =SUM(F18:AA18) -> 0
A19: 44474 | C19: Wang Wei - fund transfer | E19: 45000 | F19: =E19*1.3646 -> 61407 | M19: =-F19 -> -61407 | AB19: =SUM(F19:AA19) -> 0
A20: 44476 | C20: Wang Ji - fund transfer | D20: 61470 | M20: =-D20 -> -61470 | AB20: =SUM(D20:AA20) -> 0
A21: 44476 | C21: Yu Qichuan - fund transfer | D21: 83430 | M21: =-D21 -> -83430 | AB21: =SUM(D21:AA21) -> 0
A22: 44476 | C22: Yu Qichuan/Wang Ji - fund transfer | D22: =-D20-D21 -> -144900 | E22: =F22/1.3646 -> 106184.96 | F22: =-D22 -> 144900 | M22: 0 | AB22: =SUM(D22:AA22)-E22 -> 0
A23: 44476 | C23: Yu Qichuan - fund transfer | E23: =F23/1.3656 -> 43936.731 | F23: 60000 | M23: =-F23 -> -60000 | AB23: =SUM(D23:AA23)-E23 -> 0
A24: 44476 | C24: Wang Wei - fund transfer | E24: =F24/1.3651 -> 75049.447 | F24: 102450 | M24: =-F24 -> -102450 | AB24: =SUM(D24:AA24)-E24 -> 0
A25: 44477 | C25: Fund transferred | D25: -273.2 | E25: 200 | F25: =-D25 -> 273.2 | M25: 0 | AB25: =SUM(D25:AA25)-E25 -> 0
A26: 44477 | C26: Fund transferred | E26: -855000 | F26: =SUM(M11:M24) -> -1166680.5 | H26: =-F26 -> 1166680.5 | AB26: =SUM(D26:AA26)-E26 -> 0
A27: 44477 | C27: Bank charges | E27: -43 | F27: =E27*1.366 -> -58.738 | S27: =-F27 -> 58.738 | AB27: =SUM(D27:AA27)-E27 -> 0
A28: 44477 | C28: Bank charges | E28: -15 | F28: =E28*1.366 -> -20.49 | S28: =-F28 -> 20.49 | AB28: =SUM(D28:AA28)-E28 -> 0
A29: 44488 | C29: Incorporation fee $315+$600+Stamp$19 | D29: -934 | T29: 915 | U29: 19 | AB29: =SUM(D29:AA29)-E29 -> 0
A30: 44489 | C30: Utility fees rec'd - Ban Leong | D30: 99.84 | R30: =-D30 -> -99.84 | AB30: =SUM(D30:AA30)-E30 -> 0
A31: 44505 | C31: Bank charges | D31: -10 | S31: =-D31 -> 10 | AB31: =SUM(D31:AA31)-E31 -> 0
A32: 44530 | C32: USD a/c exchange difference | F32: =298.5*1.3686-174.02 -> 234.5071 | Z32: =-F32 -> -234.5071 | AB32: =SUM(D32:AA32)-E32 -> 0
A33: 44533 | C33: Bank charges | D33: -10 | S33: =-D33 -> 10 | AB33: =SUM(D33:AA33)-E33 -> 0
A34: 44540 | C34: Utility fees rec'd - Ban Leong | D34: 49.79 | R34: =-D34 -> -49.79 | AB34: =SUM(D34:AA34)-E34 -> 0
A35: 44558 | C35: Utility fees rec'd - Ban Leong | D35: 107.06 | R35: =-D35 -> -107.06 | AB35: =SUM(D35:AA35)-E35 -> 0
A36: 44564 | C36: Bank charges | D36: -10 | S36: =-D36 -> 10 | AB36: =SUM(D36:AA36)-E36 -> 0
A37: 44578 | C37: Utility fees rec'd - Ban Leong | D37: 24.25 | R37: =-D37 -> -24.25 | AB37: =SUM(D37:AA37)-E37 -> 0
A38: 44562 | B38: 2022-1001 | C38: MDK (S) - Utilities Jul21 to Jan22 | I38: 1650 | J38: -1650 | Q38: =1650-3023.29 -> -1373.29 | Y38: =-Q38 -> 1373.29 | AB38: =SUM(D38:AA38)-E38 -> 0
A39: 44593 | B39: 2022-1002 | C39: MDK (S) - Office car park Jul21 to Feb22 | Q39: -1400 | X39: =-Q39 -> 1400 | AB39: =SUM(D39:AA39)-E39 -> 0
A40: 44607 | B40: 2022-1003 | C40: MDK (S) - Office rent Jul21 to Feb22 | I40: 4400 | J40: =-I40 -> -4400 | Q40: =4400-25586 -> -21186 | V40: =-Q40 -> 21186 | AB40: =SUM(D40:AA40)-E40 -> 0
A41: 44593 | B41: 2022-1004 | C41: MDK (S) - Telephone & internet (Inv. 2022-1004) | Q41: -1307 | W41: =-Q41 -> 1307 | AB41: =SUM(D41:AA41)-E41 -> 0
A42: 44595 | C42: Bank charges | D42: -10 | S42: =-D42 -> 10 | AB42: =SUM(D42:AA42)-E42 -> 0
A43: 44623 | C43: Bank charges | D43: -10 | S43: =-D43 -> 10 | AB43: =SUM(D43:AA43)-E43 -> 0
A44: 44630 | C44: Utility fees rec'd - Ban Leong | D44: 89.28 | R44: =-D44 -> -89.28 | AB44: =SUM(D44:AA44)-E44 -> 0
...

Sheet Exchange.rate
A1: MAS: Financial Database - Exchange Rates
A3: Exchange Rates (Monthly)
A4: Sep 2021 to Nov 2021
A7: End of Period | C7: S$ Per Unit of US Dollar | D7: S$ Per 100 Units of Chinese Renminbi
A8: 2021 | B8: Sep | C8: 1.3611 | D8: 21.04
B9: Oct | C9: 1.3444 | D9: 21.03
B10: Nov | C10: 1.3686 | D10: 21.48
A12: * Yearly, monthly and weekly figures are end period values.
A13: * Daily figures are values as of noon.

Sheet Journal
A1: YWX HOLDING PTE LTD
A2: PERIOD ENDED 31.5.2022
A5: JOURNAL ENTRIES
F8: DR | H8: CR
F9: S$ | H9: S$
A11: 1 | B11: Utilities | F11: 566.53
C12: Utility deposit | H12: =F11 -> 566.53
B14: Being refund of utility deposit adjusted
A16: 2 | B16: Telephone & internet | F16: 216
C17: Accruals | H17: =F16 -> 216
B19: Being Apr & May telephone/internet charges accrued

Sheet Company profile
A1: YWX HOLDING PTE LTD
A4: UEN No | B4: : | C4: 202119939E
A6: Incorporation date | B6: : | C6: 7/6/2021
A8: Registered office | B8: : | C8: 66 Elias Road #07-11 Oasis @ Elias, Singapore 519941
A10: Financial year end | B10: : | C10: May
A12: Director | B12: : | C12: Yu Qichuan
A14: Secretary | B14: : | C14: Tricia Wanxuan
C15: 100 Jalan Sultan #02-44, Sultan Plaza, Singapore 199001
A17: Shareholders and their shareholdings
D19: No of shares | F19: % held
C20: Yu Qichuan | D20: 4211 | F20: =D20/10000 -> 0.4211
C21: Xia Limin | D21: 1228 | F21: =D21/10000 -> 0.1228
C22: Wang Wei | D22: 2807 | F22: =D22/10000 -> 0.2807
C23: Wang Ji | D23: 1754 | F23: =D23/10000 -> 0.1754
D24: =SUM(D20:D23) -> 10000 | F24: =SUM(F20:F23) -> 1
